Workbook

Sheet Votes
A1: Citation | B1: target_sentence | C1: context | D1: cited_title | E1: 1_ABC | F1: 2_CEBC | G1: 3_FL | H1: 4_GR | I1: 5_JA | J1: 6_JGAC | K1: 7_RAB | L1: 8_ST | M1: Answered | N1: Revealed | O1: Expected | P1: Also acceptable | Q1: Matches | R1: Rule | S1: cited_abstract | T1: passage_1 | U1: passage_2 | V1: passage_3 | W1: group_size
A2: C01 | B2: We also added the input as Layer 0 which enables the tracker to benefit from NCC tracking, hence [FORMULA]input, conv1_1, conv2_1, conv3_1, conv4_1, conv5_1[FORMULA] .In our implementation, [FORMULA] , regularization weights [FORMULA] are determined with cross-validation on YouTubeBB [[TARGET]] and are fixed for all the experiments, others parameters are similar to [CITE]. | C2: We used VGG19 network consisting of 16 convolutional and 5 max-pooling layers, as implemented in MatConvNet[CITE] and pre-trained on the ImageNet dataset for the image classification. To be constistant with [CITE] and [CITE], we used the conv layers after the pooling . We also added the input as Layer 0 which enables the tracker to benefit from NCC tracking, hence [FORMULA]input, conv1_1, conv2_1, conv3_1, conv4_1, conv5_1[FORMULA] .In our implementation, [FORMULA] , regularization weights [FORMULA] are determined with cross-validation on YouTubeBB [[TARGET]] and are fixed for all the experiments, others parameters are similar to [CITE]. | D2: YouTube-BoundingBoxes: A Large High-Precision Human-Annotated Data Set for Object Detection in Video | E2: Application | G2: Application | H2: Application | I2: Application | J2: Application | K2: Basis | L2: Background | M2: =COUNTA(E2:L2) -> 7 | N2: =TRUE() -> TRUE | O2: =IF($N2,Key!B2,"") -> Application | P2: =IF($N2,Key!C2,"") | Q2: =IF(N2,SUMPRODUCT(--(((E2:L2=Key!B2)+((Key!C2<>"")*(E2:L2=Key!C2)))>0))&" of "&COUNTA(E2:L2),"") -> 5 of 7 | R2: =IF(N2,Key!D2&": "&Key!E2,"") -> R-EV: The current work uses the target's dataset (YouTubeBB) in its own experiments: Application. | S2: We introduce a new large-scale data set of video URLs with densely-sampled object bounding box annotations called YouTube-BoundingBoxes (YT-BB). The data set consists of approximately 380,000 video segments about 19s long, automatically selected to feature objects in natural settings without editing or post-processing, with a recording quality often akin to that of a hand-held cell phone camera. The objects represent a subset of the MS COCO label set. All video segments were human-annotated with high-precision classification labels and bounding boxes at 1 frame per second. The use of a cascade of increasingly precise human annotations ensures a label accuracy above 95% for every class and tight bounding boxes. Finally, we train and evaluate well-known deep network architectures and report baseline figures for per-frame classification and localization to provide a point of comparison for future work. We also demonstrate how the temporal contiguity of video can potentially be used to improve such inferences. Please see the PDF file to find the URL to download the data. We hope the availability of such large curated corpus will spur new advances in video object detection and tracking. | T2: [Object detection] We then compared the relative difficulty of YT-BB and COCO for object detection. We used two instances of a Faster-RCNN REF detection proposal architecture [CITE] paired with an Inception-ResNet-v2 REF feature network [CITE], [CITE]. Increasing the number of detection proposal results in improved object localizations at the expense of more computationally expensive inference and training. We selected a set of hyperparameters that resulted in 1400b FLOPs per frame for inference. Both instances were partially initialized with the weights of an Inception-ResNet-v2 image classification system trained on the ImageNet 2012 Challenge data set [CITE]. One instance was subsequently trained further on YT-BB (“the YT-BB model”) and another on COCO (“the COCO model”). We evaluated the performance of each model by measuring the mean precision-recall curve across all 23 classes. These results are summarized across several standard calculations of mAP for object detection in Table REF and delineated by class in Supplementary Table REF . We find that training on YT-BB (mAP = 0.59) is easier than on COCO (mAP = 0.43). This result is consistent when measured across a range of detection box sizes. | U2: [Image classification] We started by comparing the relative difficulty of two instances of the same image classification model, one trained on YT-BB (“the YT-BB model”) and one trained on COCO (“the COCO model”). Our data set has explicit classification annotations. For COCO, we treated the presence or absence of any object localization of a class as either a positive or negative label, respectively. Both models employed an Inception-v3See Supplementary Section for GitHub locations. architecture [CITE] with logistic regression, implemented in TensorFlow[CITE]. The choice of logistic regression reflects the fact that multiple labels may be associated with a single image. Both models were initialized with the weights of an Inception-v3 image classification system pre-trained on the ImageNet 2012 Challenge data set [CITE] and subsequently fine-tuned on YT-BB/COCO individually. We measured the mean precision-recall curve across all 23 classes (excluding the “NONE” class since it is not available in COCO). These results are shown in the dark curves in Figure REF . We find that training on YT-BB (mAP = 0.93) is easier than on COCO (mAP = 0.83), which could reflect the larger amount of training data per-class available in YT-BB. | V2: [Exploiting temporal information in videos] For the object detection task, we down-weighted spurious weak object detections that appeared in single video frames but not in neighboring frames. Specifically, we artificially multiplied by [FORMULA] the confidence scores of detected objects that did not overlap significantly with previous and subsequent frame detections (IOU [FORMULA] ; confidence [FORMULA] ). Figure REF shows the effects of this manipulation on the precision-recall curves. When aggregating across all classes, temporal smoothing slightly reduces model performance (mAP = 0.36 vs mAP = 0.37). We broke down this result to expose the diversity of behavior across labels. This revealed elevated precision-recall curves for some classes (“knife”, “bus”) but lowered curves for other classes (“person”). In principle, a unified model could at least learn which classes benefit and apply the correction only to those. Despite the mixed results, this analysis suggests that taking into account the temporal structure of the video could result in better detection models. | W2: 1
A3: C02 | B3: The SINet-Caption is inspired by prior work using hierarchical LSTM for captioning task [[TARGET]], [CITE], and we extend it with the proposed recurrent higher-order interaction module so that the model can leverage the detected higher-order object interactions, as shown in Figure REF . | C3: The SINet-Caption is inspired by prior work using hierarchical LSTM for captioning task [[TARGET]], [CITE], and we extend it with the proposed recurrent higher-order interaction module so that the model can leverage the detected higher-order object interactions, as shown in Figure REF . The model consist of two LSTM layers: Attention LSTM and Language LSTM. | D3: Bottom-Up and Top-Down Attention for Image Captioning and Visual Question Answering | E3: Basis | G3: Improvement/Modification | H3: Improvement/Modification | I3: Basis | J3: Improvement/Modification | K3: Basis | L3: Basis | M3: =COUNTA(E3:L3) -> 7 | N3: =TRUE() -> TRUE | O3: =IF(N3,Key!B3,"") -> Basis | P3: =IF($N3,Key!C3,"") -> Improvement/Modification | Q3: =IF(N3,SUMPRODUCT(--(((E3:L3=Key!B3)+((Key!C3<>"")*(E3:L3=Key!C3)))>0))&" of "&COUNTA(E3:L3),"") -> 7 of 7 | R3: =IF(N3,Key!D3&": "&Key!E3,"") -> R-EV, R-IM: Inspired by [T] … and we extend it': the current work builds on the target's model as its starting point; 'extend it' can also be read as adapting the target's method. | S3: Top-down visual attention mechanisms have been used extensively in image captioning and visual question answering (VQA) to enable deeper image understanding through fine-grained analysis and even multiple steps of reasoning. In this work, we propose a combined bottom-up and top-down attention mechanism that enables attention to be calculated at the level of objects and other salient image regions. This is the natural basis for attention to be considered. Within our approach, the bottom-up mechanism (based on Faster R-CNN) proposes image regions, each with an associated feature vector, while the top-down mechanism determines feature weightings. Applying this approach to image captioning, our results on the MSCOCO test server establish a new state-of-the-art for the task, achieving CIDEr / SPICE / BLEU-4 scores of 117.9, 21.5 and 36.9, respectively. Demonstrating the broad applicability of the method, applying the same approach to VQA we obtain first place in the 2017 VQA Challenge. | T3: [Top-Down Attention LSTM] Within the captioning model, we characterize the first LSTM layer as a top-down visual attention model, and the second LSTM layer as a language model, indicating each layer with superscripts in the equations that follow. Note that the bottom-up attention model is described in sec:rcnn, and in this section its outputs are simply considered as features [FORMULA] . The input vector to the attention LSTM at each time step consists of the previous output of the language LSTM, concatenated with the mean-pooled image feature [FORMULA] and an encoding of the previously generated word, given by: [FORMULA] where [FORMULA] is a word embedding matrix for a vocabulary [FORMULA] , and [FORMULA] is one-hot encoding of the input word at timestep [FORMULA] . These inputs provide the attention LSTM with maximum context regarding the state of the language LSTM, the overall content of the image, and the partial caption output generated so far, respectively. The word embedding is learned from random initialization without pretraining. | U3: [Captioning Model] Given a set of image features [FORMULA] , our proposed captioning model uses a `soft' top-down attention mechanism to weight each feature during caption generation, using the existing partial output sequence as context. This approach is broadly similar to several previous works [CITE], [CITE], [CITE]. However, the particular design choices outlined below make for a relatively simple yet high-performing baseline model. Even without bottom-up attention, our captioning model achieves performance comparable to state-of-the-art on most evaluation metrics (refer tab:karpathy). At a high level, the captioning model is composed of two LSTM [CITE] layers using a standard implementation [CITE]. In the sections that follow we will refer to the operation of the LSTM over a single time step using the following notation: [FORMULA] | V3: [VQA Model] Given a set of spatial image features [FORMULA] , our proposed VQA model also uses a `soft' top-down attention mechanism to weight each feature, using the question representation as context. As illustrated in fig:vqa, the proposed model implements the well-known joint multimodal embedding of the question and the image, followed by a prediction of regression of scores over a set of candidate answers. This approach has been the basis of numerous previous models [CITE], [CITE], [CITE]. However, as with our captioning model, implementation decisions are important to ensure that this relatively simple model delivers high performance. The learned non-linear transformations within the network are implemented with gated hyperbolic tangent activations [CITE]. These are a special case of highway networks [CITE] that have shown a strong empirical advantage over traditional ReLU or tanh layers. Each of our `gated tanh' layers implements a function [FORMULA] with parameters [FORMULA] defined as follows: [FORMULA] | W3: 2
A4: C03 | B4: For a detailed survey we refer the reader to [[TARGET]], [CITE], [CITE], while here we provide a brief literature review. | C4: Skeleton-based action recognition has attracted growing attention in the realm of computer vision and a variety of methods have been proposed over the past decades. For a detailed survey we refer the reader to [[TARGET]], [CITE], [CITE], while here we provide a brief literature review. The early works on skeleton-based action recognition are based on hand-crafted features [CITE], [CITE], [CITE], [CITE], while recent approaches are devised by designing deep neural networks (DNNs) like convolutional neural networks (CNNs) [CITE], [CITE], [CITE] and recurrent neural networks (RNNs) [CITE], [CITE], [CITE]. In order to better capture the relationship of different joints in the spatial domain or dependency of different frames in the temporal domain, a number of works utilized the attention mechanisms [CITE], [CITE], [CITE] and graph neural networks (GNNs) [CITE], [CITE], [CITE], [CITE], [CITE] more recently. Besides, there are various works using both skeleton joints and RGB videos as inputs for action recognition [CITE], [CITE], [CITE]. For example, Verma et al. [CITE] design two deep neural networks (DNNs) models for the multi-modal inputs respectively, and use a weight product model (WPM) to fuse the softmax scores obtained from the two DNNs. Different from these works which deal with the input videos from the same dataset during training and testing phases, we study a more practical and challenging UDA setting to deal with the samples across different datasets. | D4: Space-Time Representation of People Based on 3D Skeletal Data: A Review | E4: Further Reading | G4: Further Reading | H4: Further Reading | I4: Background | J4: Further Reading | K4: Further Reading | L4: Further Reading | M4: =COUNTA(E4:L4) -> 7 | N4: =TRUE() -> TRUE | O4: =IF(N4,Key!B4,"") -> Further Reading | P4: =IF($N4,Key!C4,"") | Q4: =IF(N4,SUMPRODUCT(--(((E4:L4=Key!B4)+((Key!C4<>"")*(E4:L4=Key!C4)))>0))&" of "&COUNTA(E4:L4),"") -> 6 of 7 | R4: =IF(N4,Key!D4&": "&Key!E4,"") -> R-FR: For a detailed survey we refer the reader to [T]': a pointer, no other function. | S4: Spatiotemporal human representation based on 3D visual perception data is a rapidly growing research area. Based on the information sources, these representations can be broadly categorized into two groups based on RGB-D information or 3D skeleton data. Recently, skeleton-based human representations have been intensively studied and kept attracting an increasing attention, due to their robustness to variations of viewpoint, human body scale and motion speed as well as the realtime, online performance. This paper presents a comprehensive survey of existing space-time representations of people based on 3D skeletal data, and provides an informative categorization and analysis of these methods from the perspectives, including information modality, representation encoding, structure and transition, and feature engineering. We also provide a brief overview of skeleton acquisition devices and construction methods, enlist a number of public benchmark datasets with skeleton data, and discuss potential future research directions. | T4: [Introduction] Several survey papers were published in related research areas such as motion and activity recognition. For example, Han et al. [CITE] described the Kinect sensor and its general application in computer vision and machine intelligence. Aggarwal and Xia [CITE] recently published a review paper on human activity recognition from 3D visual data, which summarized five categories of representations based on 3D silhouettes, skeletal joints or body part locations, local spatio-temporal features, scene flow features, and local occupancy features. Several earlier surveys were also published to review methods to recognize human poses, motions, gestures, and activities [CITE], [CITE], [CITE], [CITE], [CITE], [CITE], [CITE], [CITE], [CITE], [CITE], [CITE], [CITE], as well as their applications [CITE], [CITE]. However, none of the survey papers specifically focused on 3D human representation based on skeletal data, which was the subject of numerous research papers in the literature and continues to gain popularity in recent years. The objective of this survey is to provide a comprehensive overview of 3D skeleton-based human representations mainly published in the computer vision and machine intelligence communities, which are built upon 3D human skeleton data that is assumed as the raw measurements directly from sensing hardware. We categorize and compare the reviewed approaches from multiple perspectives, including information modality, representation coding, structure and transition, and feature engineering methodology, and analyze the pros and cons of each category. Compared with the existing surveys, the main contributions of this review include: | U4: [Introduction] Since the performance of machine learning and reasoning methods heavily relies on the design of data representation [CITE], human representations are intensively investigated to address human-centered research problems (e.g., human detection, tracking, pose estimation, and action recognition). Among a large number of human representation approaches [CITE], [CITE], [CITE], [CITE], [CITE], [CITE], most of the existing 3D based methods can be broadly grouped into two categories: representations based on local features [CITE], [CITE] and skeleton-based representations [CITE], [CITE], [CITE], [CITE]. Methods based on local features detect points of interest in space-time dimensions, describe the patches centered at the points as features, and encode them (e.g., using bag-of-word models) into representations, which can locate salient regions and are relatively robust to partial occlusion. However, methods based on local features ignore spatial relationships among the features. These approaches are often incapable of identifying feature affiliations, and thus the methods are generally incapable to represent multiple individuals in the same scene. These methods are also computationally expensive because of the complexity of the procedures including keypoint detection, feature description, dictionary construction, etc. | V4: [Representations Based on Low-Level Features] Several multi-layer techniques were also implemented to create skeleton-based human representations from low-level features. In particular, deep learning approaches inherently consist of multiple layers with the intermediate and output layers encoding different levels of features [CITE]. The multi-layer deep learning approaches have attracted an increasing attention in recent several years to learn human representations directly from human joint positions [CITE], [CITE]. Inspired by the spatial pyramid method [CITE] to incorporate multi-layer image information, temporal pyramid methods were introduced and used by several skeleton-based human representations to capture the multi-layer information in the time dimension [CITE], [CITE], [CITE], [CITE], [CITE]. For example, a temporal pyramid method was proposed by Zhang et al. [CITE] to capture long-term dependencies, as illustrated in Fig. REF . In this example, a temporal sequence of eleven frames is used to represent a tennis-serve motion, and the joint of interest is the right wrist, as denoted by the red dots in Fig REF . When three levels are used in the temporal pyramid, level 1 uses human skeleton data at all time points ([FORMULA] ); level 2 selects the joints at odd time points ([FORMULA] ); and level 3 continues this selection process and keeps half of the temporal data points ([FORMULA] ) to compute long-term orientation changes. | W4: 3
A5: C04 | B5: The state-of-the-art facial alignment architectures [[TARGET]][CITE][CITE] have not been developed for the purpose of real-time inference on resource restricted devices. | C5: The state-of-the-art facial alignment architectures [[TARGET]][CITE][CITE] have not been developed for the purpose of real-time inference on resource restricted devices. However, our applications primarily target such devices. To strike a better balance for real-time applications on those platforms, the ideal architecture should minimize load and execution time while preserving alignment accuracy. | D5: Deep Alignment Network: A convolutional neural network for robust face alignment | E5: Gap | G5: Gap | H5: Gap | I5: Background | J5: Gap | K5: Gap | L5: Background | M5: =COUNTA(E5:L5) -> 7 | N5: =TRUE() -> TRUE | O5: =IF(N5,Key!B5,"") -> Gap | P5: =IF($N5,Key!C5,"") | Q5: =IF(N5,SUMPRODUCT(--(((E5:L5=Key!B5)+((Key!C5<>"")*(E5:L5=Key!C5)))>0))&" of "&COUNTA(E5:L5),"") -> 5 of 7 | R5: =IF(N5,Key!D5&": "&Key!E5,"") -> R-GAP: The limitation ('have not been developed for real-time inference') is stated about the cited architectures, citation right after them: Gap. | S5: In this paper, we propose Deep Alignment Network (DAN), a robust face alignment method based on a deep neural network architecture. DAN consists of multiple stages, where each stage improves the locations of the facial landmarks estimated by the previous stage. Our method uses entire face images at all stages, contrary to the recently proposed face alignment methods that rely on local patches. This is possible thanks to the use of landmark heatmaps which provide visual information about landmark locations estimated at the previous stages of the algorithm. The use of entire face images rather than patches allows DAN to handle face images with large variation in head pose and difficult initializations. An extensive evaluation on two publicly available datasets shows that DAN reduces the state-of-the-art failure rate by up to 70%. Our method has also been submitted for evaluation as part of the Menpo challenge. | T5: [Implementation] The Python implementation runs at 73 fps for images processed in parallel and at 45 fps for images processed sequentially on a GeForce GTX 1070 GPU. We believe that the processing speed can be further improved by optimizing the implementation of some of our custom layers, most notably the Image Transform layer. To enable reproducible research, we release the source code of our implementation as well as the models used in the experimentshttps://github.com/MarekKowalski/DeepAlignmentNetwork. The published implementation also contains an example of face tracking with the proposed method. | U5: [Conclusions] In this paper, we introduced the Deep Alignment Network - a robust face alignment method based on convolutional neural networks. Contrary to the recently proposed face alignment methods, DAN performs face alignment based on entire face images, which makes it highly robust to large variations in both initialization and head pose. Using entire face images instead of local patches extracted around landmarks is possible thanks to the use of novel landmark heatmaps which transmit the information about landmark locations between DAN stages. Extensive evaluation performed on two challenging, publicly available datasets shows that the proposed method improves the state-of-the-art failure rate by a significant margin of over 70%. Future research includes investigation of new strategies for training DAN in an end-to-end manner. We also plan to introduce learning into the estimation of the transform [FORMULA] that normalizes the shapes and images between stages. | V5: [Introduction] To summarize, the three main contributions of this work are the following: We introduce landmark heatmaps which transfer the information about current landmark location estimates between the stages of our method. This improvement allows our method to make use of the entire image of a face, instead of local patches, and avoid falling into local minima. The resulting robust face alignment method we propose in this paper reduces the failure rate by 60% on the 300W private test set [CITE] and 72% on the 300-W public test set [CITE] compared to the state of the art. Finally, we publish both the source code of our implementation of the proposed method and the models used in the experiments. | W5: 3
A6: C05 | B6: Different from existing approaches based on pre-scanned human models [CITE] or parametric body models [CITE], [CITE], [CITE], our approach implicitly reconstructs the human geometry and appearance via generalizing Neural Radiance Fields (NeRF) [[TARGET]], which uses a neural network to encode color and density as a function of location and viewing angle, and generates photo-realistic images by volume rendering. | C6: In this paper, we target to obtain photo-realistic 3D human avatars from monocular RGB videos. Different from existing approaches based on pre-scanned human models [CITE] or parametric body models [CITE], [CITE], [CITE], our approach implicitly reconstructs the human geometry and appearance via generalizing Neural Radiance Fields (NeRF) [[TARGET]], which uses a neural network to encode color and density as a function of location and viewing angle, and generates photo-realistic images by volume rendering. NeRF [CITE] has shown impressive ability in reconstructing a static scene from multi-view images, and inspires many researchers in extending NeRF to scenes with severe lighting changes [CITE] and non-rigid deformations [CITE], [CITE]. However, these approaches are uncontrollable and limited to nearly static scenes with small movements, failing to deal with human subjects with large movements. | D6: NeRF: Representing Scenes as Neural Radiance Fields for View Synthesis | E6: Application | G6: Improvement/Modification | H6: Improvement/Modification | I6: Application | J6: Improvement/Modification | K6: Application | L6: Application | M6: =COUNTA(E6:L6) -> 7 | N6: =TRUE() -> TRUE | O6: =IF(N6,Key!B6,"") -> Improvement/Modification | P6: =IF($N6,Key!C6,"") -> Basis | Q6: =IF(N6,SUMPRODUCT(--(((E6:L6=Key!B6)+((Key!C6<>"")*(E6:L6=Key!C6)))>0))&" of "&COUNTA(E6:L6),"") -> 3 of 7 | R6: =IF(N6,Key!D6&": "&Key!E6,"") -> R-IM: Our approach … via generalizing NeRF [T]': the current work extends the target's method. | S6: We present a method that achieves state-of-the-art results for synthesizing novel views of complex scenes by optimizing an underlying continuous volumetric scene function using a sparse set of input views. Our algorithm represents a scene using a fully-connected (non-convolutional) deep network, whose input is a single continuous 5D coordinate (spatial location $(x,y,z)$ and viewing direction $(\theta, \phi)$) and whose output is the volume density and view-dependent emitted radiance at that spatial location. We synthesize views by querying 5D coordinates along camera rays and use classic volume rendering techniques to project the output colors and densities into an image. Because volume rendering is naturally differentiable, the only input required to optimize our representation is a set of images with known camera poses. We describe how to effectively optimize neural radiance fields to render photorealistic novel views of scenes with complicated geometry and appearance, and demonstrate results that outperform prior work on neural rendering and view synthesis. View synthesis results are best viewed as videos, so we urge readers to view our supplementary video for convincing comparisons. | T6: [unknown] Given a dense sampling of views, photorealistic novel views can be reconstructed by simple light field sample interpolation techniques [CITE], [CITE], [CITE]. For novel view synthesis with sparser view sampling, the computer vision and graphics communities have made significant progress by predicting traditional geometry and appearance representations from observed images. One popular class of approaches uses mesh-based representations of scenes with either diffuse [CITE] or view-dependent [CITE], [CITE], [CITE] appearance. Differentiable rasterizers [CITE], [CITE], [CITE], [CITE] or pathtracers [CITE], [CITE] can directly optimize mesh representations to reproduce a set of input images using gradient descent. However, gradient-based mesh optimization based on image reprojection is often difficult, likely because of local minima or poor conditioning of the loss landscape. Furthermore, this strategy requires a template mesh with fixed topology to be provided as an initialization before optimization [CITE], which is typically unavailable for unconstrained real-world scenes. | U6: [unknown] Another class of methods use volumetric representations to address the task of high-quality photorealistic view synthesis from a set of input RGB images. Volumetric approaches are able to realistically represent complex shapes and materials, are well-suited for gradient-based optimization, and tend to produce less visually distracting artifacts than mesh-based methods. Early volumetric approaches used observed images to directly color voxel grids [CITE], [CITE], [CITE]. More recently, several methods [CITE], [CITE], [CITE], [CITE], [CITE], [CITE], [CITE], [CITE] have used large datasets of multiple scenes to train deep networks that predict a sampled volumetric representation from a set of input images, and then use either alpha-compositing [CITE] or learned compositing along rays to render novel views at test time. Other works have optimized a combination of convolutional networks (CNNs) and sampled voxel grids for each specific scene, such that the CNN can compensate for discretization artifacts from low resolution voxel grids [CITE] or allow the predicted voxel grids to vary based on input time or animation controls [CITE]. While these volumetric techniques have achieved impressive results for novel view synthesis, their ability to scale to higher resolution imagery is fundamentally limited by poor time and space complexity due to their discrete sampling — rendering higher resolution images requires a finer sampling of 3D space. We circumvent this problem by instead encoding a continuous volume within the parameters of a deep fully-connected neural network, which not only produces significantly higher quality renderings than prior volumetric approaches, but also requires just a fraction of the storage cost of those sampled volumetric representations. [FIGURE] | V6: [Introduction] Differentiable rasterizers [CITE], [CITE], [CITE], [CITE] or pathtracers [CITE], [CITE] can directly optimize mesh representations to reproduce a set of input images using gradient descent. However, gradient-based mesh optimization based on image reprojection is often difficult, likely because of local minima or poor conditioning of the loss landscape. Furthermore, this strategy requires a template mesh with fixed topology to be provided as an initialization before optimization [CITE], which is typically unavailable for unconstrained real-world scenes. Another class of methods use volumetric representations to address the task of high-quality photorealistic view synthesis from a set of input RGB images. Volumetric approaches are able to realistically represent complex shapes and materials, are well-suited for gradient-based optimization, and tend to produce less visually distracting artifacts than mesh-based methods. Early volumetric approaches used observed images to directly color voxel grids [CITE], [CITE], [CITE]. More recently, several methods [CITE], [CITE], [CITE], [CITE], [CITE], [CITE], [CITE], [CITE] have used large datasets of multiple scenes to train deep networks that predict a sampled volumetric representation from a set of input images, and then use either alpha-compositing [CITE] or learned compositing along rays to render novel views at test time. Other works have optimized a combination of convolutional networks (CNNs) and sampled voxel grids for each specific scene, such that the CNN can compensate for discretization artifacts from low resolution voxel grids [CITE] or allow the predicted voxel grids to vary based on input time or animation controls [CITE]. While these volumetric techniques have achieved impressive results for novel view synthesis, their ability to scale to higher resolution imagery is fundamentally limited by poor time and space complexity due to their discrete sampling — rendering higher resolution images requires a finer sampling of 3D space. | W6: 1
A7: C06 | B7: [CITE] propose “SharpMask”, a feed-forward architecture in which a convolutional network first generates coarse-resolution object masks, and then upsampling modules refine these masks at the original image resolution (resulting in an overall architecture similar to U-Net as developed by [[TARGET]]). | C7: A variety of papers have recently introduced “instance” segmentation methods that utilize recurrent or feed-forward networks to directly produce segmentation masks from an image. For example, [CITE] propose a recurrent architecture that at each iteration of the network dynamics produces a complete segmentation mask for a single object in the image. [CITE] propose “SharpMask”, a feed-forward architecture in which a convolutional network first generates coarse-resolution object masks, and then upsampling modules refine these masks at the original image resolution (resulting in an overall architecture similar to U-Net as developed by [[TARGET]]). Our approach builds on this prior work, but is distinct in several respects: | D7: U-Net: Convolutional Networks for Biomedical Image Segmentation | E7: Basis | G7: Comparison | H7: Basis | I7: Comparison | J7: Comparison | K7: Basis | L7: Comparison | M7: =COUNTA(E7:L7) -> 7 | N7: =TRUE() -> TRUE | O7: =IF(N7,Key!B7,"") -> Comparison | P7: =IF($N7,Key!C7,"") | Q7: =IF(N7,SUMPRODUCT(--(((E7:L7=Key!B7)+((Key!C7<>"")*(E7:L7=Key!C7)))>0))&" of "&COUNTA(E7:L7),"") -> 4 of 7 | R7: =IF(N7,Key!D7&": "&Key!E7,"") -> R-CMP: Another cited work (SharpMask) is likened to the target ('similar to U-Net as developed by [T]'): Comparison between cited works. | S7: There is large consent that successful training of deep networks requires many thousand annotated training samples. In this paper, we present a network and training strategy that relies on the strong use of data augmentation to use the available annotated samples more efficiently. The architecture consists of a contracting path to capture context and a symmetric expanding path that enables precise localization. We show that such a network can be trained end-to-end from very few images and outperforms the prior best method (a sliding-window convolutional network) on the ISBI challenge for segmentation of neuronal structures in electron microscopic stacks. Using the same network trained on transmitted light microscopy images (phase contrast and DIC) we won the ISBI cell tracking challenge 2015 in these categories by a large margin. Moreover, the network is fast. Segmentation of a 512x512 image takes less than a second on a recent GPU. The full implementation (based on Caffe) and the trained networks are available at http://lmb.informatik.uni-freiburg.de/people/ronneber/u-net . | T7: [Introduction] Obviously, the strategy in Ciresan et al. [CITE] has two drawbacks. First, it is quite slow because the network must be run separately for each patch, and there is a lot of redundancy due to overlapping patches. Secondly, there is a trade-off between localization accuracy and the use of context. Larger patches require more max-pooling layers that reduce the localization accuracy, while small patches allow the network to see only little context. More recent approaches [CITE], [CITE] proposed a classifier output that takes into account the features from multiple layers. Good localization and the use of context are possible at the same time. [FIGURE] In this paper, we build upon a more elegant architecture, the so-called “fully convolutional network” [CITE]. We modify and extend this architecture such that it works with very few training images and yields more precise segmentations; see fig:u-net. The main idea in [CITE] is to supplement a usual contracting network by successive layers, where pooling operators are replaced by upsampling operators. Hence, these layers increase the resolution of the output. In order to localize, high resolution features from the contracting path are combined with the upsampled output. A successive convolution layer can then learn to assemble a more precise output based on this information. | U7: [Training] In deep networks with many convolutional layers and different paths through the network, a good initialization of the weights is extremely important. Otherwise, parts of the network might give excessive activations, while other parts never contribute. Ideally the initial weights should be adapted such that each feature map in the network has approximately unit variance. For a network with our architecture (alternating convolution and ReLU layers) this can be achieved by drawing the initial weights from a Gaussian distribution with a standard deviation of [FORMULA] , where [FORMULA] denotes the number of incoming nodes of one neuron [CITE]. E.g. for a 3x3 convolution and 64 feature channels in the previous layer [FORMULA] . | V7: [Introduction] One important modification in our architecture is that in the upsampling part we have also a large number of feature channels, which allow the network to propagate context information to higher resolution layers. As a consequence, the expansive path is more or less symmetric to the contracting path, and yields a u-shaped architecture. The network does not have any fully connected layers and only uses the valid part of each convolution, i.e., the segmentation map only contains the pixels, for which the full context is available in the input image. This strategy allows the seamless segmentation of arbitrarily large images by an overlap-tile strategy (see fig:overlap-tile). To predict the pixels in the border region of the image, the missing context is extrapolated by mirroring the input image. This tiling strategy is important to apply the network to large images, since otherwise the resolution would be limited by the GPU memory. [FIGURE] As for our tasks there is very little training data available, we use excessive data augmentation by applying elastic deformations to the available training images. This allows the network to learn invariance to such deformations, without the need to see these transformations in the annotated image corpus. This is particularly important in biomedical segmentation, since deformation used to be the most common variation in tissue and realistic deformations can be simulated efficiently. The value of data augmentation for learning invariance has been shown in Dosovitskiy et al. [CITE] in the scope of unsupervised feature learning. | W7: 1
A8: C07 | B8: This shortcoming is severe since certain adversarial perturbations created by the white-box attacks can fool other unrelated models owing to the adversarial transferability phenomenon [[TARGET]]. | C8: While face recognition is improved significantly over recent years thanks to the breakthroughs in deep learning, the face recognition models are prone to adversarial perturbations [CITE]. This shortcoming is severe since certain adversarial perturbations created by the white-box attacks can fool other unrelated models owing to the adversarial transferability phenomenon [[TARGET]]. One of the most thoroughly benchmarked defenses against adversarial attacks is adversarial training [CITE], [CITE], in which a CNN model is trained on adversarial examples generated by itself. Despite the considerable improvement in adversarial learning, recent works on biometrics mostly rest on developing robust face recognition [CITE], face identification [CITE], and face verification systems [CITE]. However, in the case of the morphed images, it has received far less attention to generate adversarial examples and benchmark their robustness against adversarial perturbations. To alleviate this threat, we augment the training dataset of the target model with multi-adversarial perturbations transferred from different pre-trained models. | D8: Enhancing Adversarial Example Transferability with an Intermediate Level Attack | E8: Evidence | G8: Evidence | H8: Evidence | I8: Evidence | J8: Evidence | K8: Background | L8: Background | M8: =COUNTA(E8:L8) -> 7 | N8: =TRUE() -> TRUE | O8: =IF(N8,Key!B8,"") -> Evidence | P8: =IF($N8,Key!C8,"") | Q8: =IF(N8,SUMPRODUCT(--(((E8:L8=Key!B8)+((Key!C8<>"")*(E8:L8=Key!C8)))>0))&" of "&COUNTA(E8:L8),"") -> 5 of 7 | R8: =IF(N8,Key!D8&": "&Key!E8,"") -> R-EV: The target backs the authors' claim that perturbations transfer to other models (cited at the end of the claim): Evidence. | S8: Neural networks are vulnerable to adversarial examples, malicious inputs crafted to fool trained models. Adversarial examples often exhibit black-box transfer, meaning that adversarial examples for one model can fool another model. However, adversarial examples are typically overfit to exploit the particular architecture and feature representation of a source model, resulting in sub-optimal black-box transfer attacks to other target models. We introduce the Intermediate Level Attack (ILA), which attempts to fine-tune an existing adversarial example for greater black-box transferability by increasing its perturbation on a pre-specified layer of the source model, improving upon state-of-the-art methods. We show that we can select a layer of the source model to perturb without any knowledge of the target models while achieving high transferability. Additionally, we provide some explanatory insights regarding our method and the effect of optimizing for adversarial examples using intermediate feature maps. Our code is available at https://github.com/CUVL/Intermediate-Level-Attack. | T8: [Introduction] Adversarial attacks can be classified into two categories: white-box attacks and black-box attacks. In white-box attacks, information of the model (i.e., its architecture, gradient information, etc.) is accessible, whereas in black-box attacks, the attackers have access only to the prediction. Black-box attacks are a bigger concern for real-world applications for the obvious reason that such applications typically will not reveal their models publicly, especially when security is a concern (e.g., CNN-based objectionable content filters in social media). Consequently, black-box attacks are mostly focused on the transferability of adversarial examples . Moreover, adversarial examples generated using white-box attacks will sometimes successfully attack an unrelated model. This phenomenon is known as “transferability.” However, black-box success rates for an attack are nearly always lower than those of white-box attacks, suggesting that the white-box attacks overfit on the source model. Different adversarial attacks transfer at different rates, but most of them are not optimizing specifically for transferability. This paper aims to achieve the goal of increasing the transferability of a given adversarial example. To this end, we propose a novel method that fine-tunes a given adversarial example through examining its representations in intermediate feature maps that we call Intermediate Level Attack (ILA). | U8: [Introduction] Adversarial examples are small, imperceptible perturbations of images carefully crafted to fool trained models , . Studies such as have shown that Convolutional Neural Networks (CNNs) are particularly vulnerable to such adversarial attacks. The existence of these adversarial attacks suggests that our architectures and training procedures produce fundamental blind spots in our models, and that our models are not learning the same features that humans do. These adversarial attacks are of interest for more than just the theoretical issues they pose – concerns have also been raised over the vulnerability of CNNs to these perturbations in the real world, where they are used for mission-critical applications such as online content filtration systems and self-driving cars , . As a result, a great deal of effort has been dedicated to studying adversarial perturbations. Much of the literature has been dedicated to the development of new attacks that use different perceptibility metrics , , , security settings (black box/white box) , , as well as increasing efficiency . Defending against adversarial attacks is also well studied. In particular, adversarial training, where models are trained on adversarial examples, has been shown to be effective under certain assumptions , . | V8: [Intermediate-layer Adversarial Attacks] A small number of studies have focused on perturbing mid-layer outputs. These include , which perturbs mid-layer activations by crafting a single universal perturbation that produces as many spurious mid-layer activations as possible. Another is Feature Adversary Attack , , which performs a targeted attack by minimizing the distance of the representations of two images in internal neural network layers (instead of in the output layer). However, instead of emphasizing adversarial transferability, it focuses more on internal representations. Results in the paper show that even when given a guide image and a dissimilar target image, it is possible to perturb the target image to produce an embedding similar to that of the guide image. Two other related works , focus on perturbing intermediate activation maps for the purpose of increasing adversarial transferability in a method similar to that of , except they focus on black-box transferability. Their method does not focus on fine-tuning existing adversarial examples and differs significantly in attack methodology from ours. | W8: 1
A9: C08 | B9: Flow-guided feature aggregation [[TARGET]], on the other hand, tries to improve accuracy by aggregating features from nearby frames. | C9: Object detection from video. Others have also exploited the temporal properties of video to improve object detection. T-CNN [CITE] regularizes detection results with tracking output. In Detect and Track [CITE], an end-to-end architecture is proposed which incorporates detection and tracking to improve accuracy. Both methods require future frames to predict current frame, therefore they are non-causal. Deep feature flow [CITE] exploits temporal redundancy between neighboring frames by estimating optical flow with FlowNet [CITE]. It achieves high speed-ups by skipping feature extraction for non-key frames. Flow-guided feature aggregation [[TARGET]], on the other hand, tries to improve accuracy by aggregating features from nearby frames. In [CITE], a unified approach of exploiting feature flow is presented, which improves both the detection accuracy and the speed. A similar flow based hardware solution is proposed in [FORMULA] [CITE]. | D9: Flow-Guided Feature Aggregation for Video Object Detection | E9: Background | G9: Comparison | H9: Comparison | I9: Comparison | J9: Comparison | K9: Background | L9: Comparison | M9: =COUNTA(E9:L9) -> 7 | N9: =TRUE() -> TRUE | O9: =IF(N9,Key!B9,"") -> Comparison | P9: =IF($N9,Key!C9,"") -> Background | Q9: =IF(N9,SUMPRODUCT(--(((E9:L9=Key!B9)+((Key!C9<>"")*(E9:L9=Key!C9)))>0))&" of "&COUNTA(E9:L9),"") -> 7 of 7 | R9: =IF(N9,Key!D9&": "&Key!E9,"") -> R-CMP: On the other hand' contrasts the target's goal (accuracy) with the previous cited work's (speed); read as a plain description it is Background. | S9: Extending state-of-the-art object detectors from image to video is challenging. The accuracy of detection suffers from degenerated object appearances in videos, e.g., motion blur, video defocus, rare poses, etc. Existing work attempts to exploit temporal information on box level, but such methods are not trained end-to-end. We present flow-guided feature aggregation, an accurate and end-to-end learning framework for video object detection. It leverages temporal coherence on feature level instead. It improves the per-frame features by aggregation of nearby features along the motion paths, and thus improves the video recognition accuracy. Our method significantly improves upon strong single-frame baselines in ImageNet VID, especially for more challenging fast moving objects. Our framework is principled, and on par with the best engineered systems winning the ImageNet VID challenges 2016, without additional bells-and-whistles. The proposed method, together with Deep Feature Flow, powered the winning entry of ImageNet VID challenges 2017. The code is available at https://github.com/msracver/Flow-Guided-Feature-Aggregation. | T9: [Introduction] Nevertheless, the video has rich information about the same object instance, usually observed in multiple “snapshots" in a short time. Such temporal information is exploited in existing video object detection methods [CITE], [CITE], [CITE], [CITE] in a simple way. These methods firstly apply object detectors in single frames and then assemble the detected bounding boxes across temporal dimension in a dedicated post processing step. This step relies on off-the-shelf motion estimation such as optical flow, and hand-crafted bounding box association rules such as object tracking. In general, such methods manipulate the single-frame detection boxes with mediocre qualities but do not improve the detection quality. The performance improvement is from heuristic post-processing instead of principled learning. There is no end-to-end training. In this work, these techniques are called box level methods. We attempt to take a deeper look at video object detection. We seek to improve the detection or recognition quality by exploiting temporal information, in a principled way. As motivated by the success in image recognition [CITE], feature matters, and we propose to improve the per-frame feature learning by temporal aggregation. Note that the features of the same object instance are usually not spatially aligned across frames due to video motion. A naive feature aggregation may even deteriorate the performance, as elaborated in Table REF (b) later. This suggests that it is critical to model the motion during learning. | U9: [Introduction] In this work, we propose flow-guided feature aggregation (FGFA). As illustrated in Figure REF , the feature extraction network is applied on individual frames to produce the per-frame feature maps. To enhance the features at a reference frame, an optical flow network [CITE] estimates the motions between the nearby frames and the reference frame. The feature maps from nearby frames are warped to the reference frame according to the flow motion. The warped features maps, as well as its own feature maps on the reference frame, are aggregated according to an adaptive weighting network. The resulting aggregated feature maps are then fed to the detection network to produce the detection result on the reference frame. All the modules of feature extraction, flow estimation, feature aggregation, and detection are trained end-to-end. Compared with box level methods, our approach works on feature level, performs end-to-end learning and is complementary (, to Seq-NMS [CITE]). It improves the per-frame features and generates high quality bounding boxes. The boxes can be further refined by box-level methods. Our approach is evaluated on the large-scale ImageNet VID dataset [CITE]. Rigorous ablation study verifies that it is effective and significantly improves upon strong single-frame baselines. Combination with box-level methods produces further improvement. We report object detection accuracy on par with the best engineered systems winning the ImageNet VID challenges, without additional bells-and-whistles (, model ensembling, multi-scale training/testing, ). | V9: [Introduction] Recent years have witnessed significant progress in object detection [CITE]. State-of-the-art methods share a similar two-stage structure. Deep Convolutional Neural Networks (CNNs) [CITE], [CITE], [CITE], [CITE] are firstly applied to generate a set of feature maps over the whole input image. A shallow detection-specific network [CITE], [CITE], [CITE], [CITE], [CITE] then generates the detection results from the feature maps. These methods achieve excellent results in still images. However, directly applying them for video object detection is challenging. The recognition accuracy suffers from deteriorated object appearances in videos that are seldom observed in still images, such as motion blur, video defocus, rare poses, etc (See an example in Figure REF and more in Figure REF ). As quantified in experiments, a state-of-the-art still-image object detector (R-FCN [CITE] + ResNet-101 [CITE]) deteriorates remarkably for fast moving objects (Table REF (a)). | W9: 1
A10: C09 | B10: Each layer will take the output of the previous layer and the original input of the dense block as inputs, following [[TARGET]]. | C10: We implement our model based on U-Net [CITE], which is also applied in the Traffic4cast 2019 competition and achieved the best results. As shown in Figure REF , it consists of 8 dense blocks and 7 transpose convolutional layers. The output of the [FORMULA] -th dense block will be input to the [FORMULA] -th transpose convolutional layer, which is a shortcut to retrieval more information from the original image. We also use these shortcuts inside the dense blocks. Each dense block has 4 convolutional layers. Each layer will take the output of the previous layer and the original input of the dense block as inputs, following [[TARGET]]. Dense blocks are followed by average pooling to half the size of the feature maps. The last dense block is followed by a single convolutional layer. [FIGURE] | D10: Densely Connected Convolutional Networks | E10: Application | G10: Basis | H10: Application | I10: Background | J10: Application | K10: Application | L10: Application | M10: =COUNTA(E10:L10) -> 7 | N10: =TRUE() -> TRUE | O10: =IF(N10,Key!B10,"") -> Application | P10: =IF($N10,Key!C10,"") -> Basis | Q10: =IF(N10,SUMPRODUCT(--(((E10:L10=Key!B10)+((Key!C10<>"")*(E10:L10=Key!C10)))>0))&" of "&COUNTA(E10:L10),"") -> 6 of 7 | R10: =IF(N10,Key!D10&": "&Key!E10,"") -> R-EV: The dense connectivity of the target is used as is in the current model ('following [T]'): Application. | S10: Recent work has shown that convolutional networks can be substantially deeper, more accurate, and efficient to train if they contain shorter connections between layers close to the input and those close to the output. In this paper, we embrace this observation and introduce the Dense Convolutional Network (DenseNet), which connects each layer to every other layer in a feed-forward fashion. Whereas traditional convolutional networks with L layers have L connections - one between each layer and its subsequent layer - our network has L(L+1)/2 direct connections. For each layer, the feature-maps of all preceding layers are used as inputs, and its own feature-maps are used as inputs into all subsequent layers. DenseNets have several compelling advantages: they alleviate the vanishing-gradient problem, strengthen feature propagation, encourage feature reuse, and substantially reduce the number of parameters. We evaluate our proposed architecture on four highly competitive object recognition benchmark tasks (CIFAR-10, CIFAR-100, SVHN, and ImageNet). DenseNets obtain significant improvements over the state-of-the-art on most of them, whilst requiring less computation to achieve high performance. Code and pre-trained models are available at https://github.com/liuzhuang13/DenseNet . | T10: [Implementation Details.] On all datasets except ImageNet, the DenseNet used in our experiments has three dense blocks that each has an equal number of layers. Before entering the first dense block, a convolution with 16 (or twice the growth rate for DenseNet-BC) output channels is performed on the input images. For convolutional layers with kernel size 3[FORMULA] 3, each side of the inputs is zero-padded by one pixel to keep the feature-map size fixed. We use 1[FORMULA] 1 convolution followed by 2[FORMULA] 2 average pooling as transition layers between two contiguous dense blocks. At the end of the last dense block, a global average pooling is performed and then a softmax classifier is attached. The feature-map sizes in the three dense blocks are 32[FORMULA] 32, 16[FORMULA] 16, and 8[FORMULA] 8, respectively. We experiment with the basic DenseNet structure with configurations [FORMULA] , [FORMULA] and [FORMULA] . For DenseNet-BC, the networks with configurations [FORMULA] , [FORMULA] and [FORMULA] are evaluated. In our experiments on ImageNet, we use a DenseNet-BC structure with 4 dense blocks on 224[FORMULA] 224 input images. The initial convolution layer comprises [FORMULA] convolutions of size 7[FORMULA] 7 with stride 2; the number of feature-maps in all other layers also follow from setting [FORMULA] . The exact network configurations we used on ImageNet are shown in Table REF . | U10: [Pooling layers.] The concatenation operation used in Eq. (REF ) is not viable when the size of feature-maps changes. However, an essential part of convolutional networks is down-sampling layers that change the size of feature-maps. To facilitate down-sampling in our architecture we divide the network into multiple densely connected dense blocks; see Figure REF . We refer to layers between blocks as transition layers, which do convolution and pooling. The transition layers used in our experiments consist of a batch normalization layer and an 1[FORMULA] 1 convolutional layer followed by a 2[FORMULA] 2 average pooling layer. | V10: [Compression.] To further improve model compactness, we can reduce the number of feature-maps at transition layers. If a dense block contains [FORMULA] feature-maps, we let the following transition layer generate [FORMULA] output feature-maps, where [FORMULA] is referred to as the compression factor. When [FORMULA] , the number of feature-maps across transition layers remains unchanged. We refer the DenseNet with [FORMULA] as DenseNet-C, and we set [FORMULA] in our experiment. When both the bottleneck and transition layers with [FORMULA] are used, we refer to our model as DenseNet-BC. | W10: 1
